<?xml version="1.0" ?>
<!-- =================================================================================== -->
<!-- |    This document was autogenerated by xacro from src/robot_base/urdf/agrobot.xacro | -->
<!-- |    EDITING THIS FILE BY HAND IS NOT RECOMMENDED                                 | -->
<!-- =================================================================================== -->
<robot name="agrobot">
  <!-- ======================== 常用颜色 ======================== -->
  <material name="orange">
    <color rgba="1.0 0.5 0.2 1.0"/>
  </material>
  <material name="gray">
    <color rgba="0.5 0.5 0.5 1.0"/>
  </material>
  <material name="dark_gray">
    <color rgba="0.3 0.3 0.3 1.0"/>
  </material>
  <material name="blue">
    <color rgba="0.2 0.4 0.8 0.5"/>
  </material>
  <material name="black">
    <color rgba="0.1 0.1 0.1 1.0"/>
  </material>
  <material name="red">
    <color rgba="0.8 0.2 0.2 1.0"/>
  </material>
  <material name="green">
    <color rgba="0.2 0.8 0.2 1.0"/>
  </material>
  <material name="white">
    <color rgba="0.9 0.9 0.9 1.0"/>
  </material>
  <material name="silver">
    <color rgba="0.7 0.7 0.7 1.0"/>
  </material>
  <!-- ======================== 车体结构 ======================== -->
  <link name="base_footprint"/>
  <joint name="base_joint" type="fixed">
    <parent link="base_footprint"/>
    <child link="base_link"/>
    <origin rpy="0 0 0" xyz="0 0 0.04100000000000001"/>
  </joint>
  <link name="base_link">
    <visual>
      <geometry>
        <box size="0.65 0.5 0.163"/>
      </geometry>
      <material name="blue"/>
    </visual>
    <collision>
      <geometry>
        <box size="0.65 0.5 0.163"/>
      </geometry>
    </collision>
    <inertial>
      <mass value="50"/>
      <inertia ixx="1.1523708333333331" ixy="0" ixz="0" iyy="1.8711208333333333" iyz="0" izz="2.8020833333333335"/>
    </inertial>
  </link>
  <joint name="base_middle_joint" type="fixed">
    <parent link="base_link"/>
    <child link="base_middle_link"/>
    <origin rpy="0 0 0" xyz="0 0 0.1145"/>
  </joint>
  <link name="base_middle_link">
    <visual>
      <geometry>
        <box size="0.498 0.348 0.066"/>
      </geometry>
      <material name="blue"/>
    </visual>
    <collision>
      <geometry>
        <box size="0.498 0.348 0.066"/>
      </geometry>
    </collision>
    <inertial>
      <mass value="50"/>
      <inertia ixx="0.5227499999999998" ixy="0" ixz="0" iyy="1.0514999999999999" iyz="0" izz="2.8020833333333335"/>
    </inertial>
  </link>
  <!-- ======================== IMU传感器 ======================== -->
  <!-- IMU安装在机器人中心位置，与base_link重合 -->
  <link name="imu_link">
    <visual>
      <origin rpy="0 0 0" xyz="0 0 0"/>
      <geometry>
        <box size="0.02 0.02 0.01"/>
        <!-- 小盒子表示IMU -->
      </geometry>
      <material name="green"/>
    </visual>
    <collision>
      <origin rpy="0 0 0" xyz="0 0 0"/>
      <geometry>
        <box size="0.02 0.02 0.01"/>
      </geometry>
    </collision>
    <inertial>
      <mass value="0.01"/>
      <inertia ixx="1e-6" ixy="0" ixz="0" iyy="1e-6" iyz="0" izz="1e-6"/>
    </inertial>
  </link>
  <joint name="imu_joint" type="fixed">
    <parent link="base_link"/>
    <child link="imu_link"/>
    <origin rpy="0 0 0" xyz="0 0 0"/>
    <!-- {{ AURA-X: Fix - IMU安装在base_link中心位置，作为tracking frame. }} -->
  </joint>
  <link name="rear_l_caster_link">
    <visual>
      <origin rpy="1.570796326795 0 0" xyz="0 0 0"/>
      <geometry>
        <cylinder length="0.045" radius="0.0275"/>
      </geometry>
      <material name="gray"/>
    </visual>
    <collision>
      <origin rpy="1.570796326795 0 0" xyz="0 0 0"/>
      <geometry>
        <cylinder length="0.045" radius="0.0275"/>
      </geometry>
    </collision>
    <inertial>
      <origin rpy="1.570796326795 0 0" xyz="0 0 0"/>
      <mass value="0.1"/>
      <inertia ixx="3.578125e-05" ixy="0" ixz="0" iyy="3.578125e-05" iyz="0" izz="3.7812500000000004e-05"/>
    </inertial>
  </link>
  <joint name="rear_l_caster_joint" type="fixed">
    <parent link="base_link"/>
    <child link="rear_l_caster_link"/>
    <origin rpy="0 0 0" xyz="-0.25 0.18 -0.101"/>
  </joint>
  <link name="rear_r_caster_link">
    <visual>
      <origin rpy="1.570796326795 0 0" xyz="0 0 0"/>
      <geometry>
        <cylinder length="0.045" radius="0.0275"/>
      </geometry>
      <material name="gray"/>
    </visual>
    <collision>
      <origin rpy="1.570796326795 0 0" xyz="0 0 0"/>
      <geometry>
        <cylinder length="0.045" radius="0.0275"/>
      </geometry>
    </collision>
    <inertial>
      <origin rpy="1.570796326795 0 0" xyz="0 0 0"/>
      <mass value="0.1"/>
      <inertia ixx="3.578125e-05" ixy="0" ixz="0" iyy="3.578125e-05" iyz="0" izz="3.7812500000000004e-05"/>
    </inertial>
  </link>
  <joint name="rear_r_caster_joint" type="fixed">
    <parent link="base_link"/>
    <child link="rear_r_caster_link"/>
    <origin rpy="0 0 0" xyz="-0.25 -0.18 -0.101"/>
  </joint>
  <link name="front_caster_link">
    <visual>
      <origin rpy="1.570796326795 0 0" xyz="0 0 0"/>
      <geometry>
        <cylinder length="0.045" radius="0.0275"/>
      </geometry>
      <material name="gray"/>
    </visual>
    <collision>
      <origin rpy="1.570796326795 0 0" xyz="0 0 0"/>
      <geometry>
        <cylinder length="0.045" radius="0.0275"/>
      </geometry>
    </collision>
    <inertial>
      <origin rpy="1.570796326795 0 0" xyz="0 0 0"/>
      <mass value="0.1"/>
      <inertia ixx="3.578125e-05" ixy="0" ixz="0" iyy="3.578125e-05" iyz="0" izz="3.7812500000000004e-05"/>
    </inertial>
  </link>
  <joint name="front_caster_joint" type="fixed">
    <parent link="base_link"/>
    <child link="front_caster_link"/>
    <origin rpy="0 0 0" xyz="0.25 0 -0.101"/>
  </joint>
  <link name="left_wheel_link">
    <visual>
      <origin rpy="1.570796326795 0 0" xyz="0 0 0"/>
      <geometry>
        <cylinder length="0.045" radius="0.0875"/>
      </geometry>
      <material name="black"/>
    </visual>
    <collision>
      <origin rpy="1.570796326795 0 0" xyz="0 0 0"/>
      <geometry>
        <cylinder length="0.045" radius="0.0875"/>
      </geometry>
    </collision>
    <inertial>
      <origin rpy="1.570796326795 0 0" xyz="0 0 0"/>
      <mass value="0.5"/>
      <inertia ixx="0.0010414062499999998" ixy="0" ixz="0" iyy="0.0010414062499999998" iyz="0" izz="0.0019140624999999997"/>
    </inertial>
  </link>
  <joint name="left_wheel_joint" type="continuous">
    <parent link="base_link"/>
    <child link="left_wheel_link"/>
    <origin rpy="0 0 0" xyz="0 0.2 -0.04100000000000001"/>
    <axis xyz="0 1 0"/>
    <limit effort="10.0" velocity="10.0"/>
    <dynamics damping="0.1" friction="0.1"/>
  </joint>
  <link name="right_wheel_link">
    <visual>
      <origin rpy="1.570796326795 0 0" xyz="0 0 0"/>
      <geometry>
        <cylinder length="0.045" radius="0.0875"/>
      </geometry>
      <material name="black"/>
    </visual>
    <collision>
      <origin rpy="1.570796326795 0 0" xyz="0 0 0"/>
      <geometry>
        <cylinder length="0.045" radius="0.0875"/>
      </geometry>
    </collision>
    <inertial>
      <origin rpy="1.570796326795 0 0" xyz="0 0 0"/>
      <mass value="0.5"/>
      <inertia ixx="0.0010414062499999998" ixy="0" ixz="0" iyy="0.0010414062499999998" iyz="0" izz="0.0019140624999999997"/>
    </inertial>
  </link>
  <joint name="right_wheel_joint" type="continuous">
    <parent link="base_link"/>
    <child link="right_wheel_link"/>
    <origin rpy="0 0 0" xyz="0 -0.2 -0.04100000000000001"/>
    <axis xyz="0 1 0"/>
    <limit effort="10.0" velocity="10.0"/>
    <dynamics damping="0.1" friction="0.1"/>
  </joint>
  <link name="right_camera">
    <visual>
      <origin rpy="0 0 0" xyz="0 0 0"/>
      <geometry>
        <box size="0.05 0.05 0.03"/>
      </geometry>
      <material name="red"/>
    </visual>
    <collision>
      <origin rpy="0 0 0" xyz="0 0 0"/>
      <geometry>
        <box size="0.05 0.05 0.03"/>
      </geometry>
    </collision>
    <inertial>
      <origin rpy="0 0 0" xyz="0 0 0"/>
      <mass value="0.05"/>
      <inertia ixx="1.4166666666666668e-05" ixy="0" ixz="0" iyy="1.4166666666666668e-05" iyz="0" izz="2.083333333333334e-05"/>
    </inertial>
  </link>
  <joint name="camera_joint" type="fixed">
    <parent link="base_link"/>
    <child link="right_camera"/>
    <origin rpy="0 1.570796326795 1.570796326795" xyz="0 0.23 0.17250000000000001"/>
  </joint>
  <link name="rightFront_laser_link">
    <visual>
      <origin rpy="0 0 0" xyz="0 0 0"/>
      <geometry>
        <cylinder length="0.05" radius="0.032"/>
      </geometry>
      <material name="red"/>
    </visual>
    <collision>
      <origin rpy="0 0 0" xyz="0 0 0"/>
      <geometry>
        <cylinder length="0.05" radius="0.032"/>
      </geometry>
    </collision>
    <inertial>
      <origin rpy="0 0 0" xyz="0 0 0"/>
      <mass value="0.05"/>
      <inertia ixx="4.643333333333334e-05" ixy="0" ixz="0" iyy="4.643333333333334e-05" iyz="0" izz="5.1200000000000004e-05"/>
    </inertial>
  </link>
  <joint name="rightFront_laser_joint" type="fixed">
    <parent link="base_link"/>
    <child link="rightFront_laser_link"/>
    <origin rpy="0 0 -0.7853981633975" xyz="0.27 -0.2 0.10650000000000001"/>
  </joint>
  <link name="leftRear_laser_link">
    <visual>
      <origin rpy="0 0 0" xyz="0 0 0"/>
      <geometry>
        <cylinder length="0.05" radius="0.032"/>
      </geometry>
      <material name="red"/>
    </visual>
    <collision>
      <origin rpy="0 0 0" xyz="0 0 0"/>
      <geometry>
        <cylinder length="0.05" radius="0.032"/>
      </geometry>
    </collision>
    <inertial>
      <origin rpy="0 0 0" xyz="0 0 0"/>
      <mass value="0.05"/>
      <inertia ixx="4.643333333333334e-05" ixy="0" ixz="0" iyy="4.643333333333334e-05" iyz="0" izz="5.1200000000000004e-05"/>
    </inertial>
  </link>
  <joint name="leftRear_laser_joint" type="fixed">
    <parent link="base_link"/>
    <child link="leftRear_laser_link"/>
    <origin rpy="0 0 2.3461944901925005" xyz="-0.28 0.19 0.10650000000000001"/>
  </joint>
  <!-- ======================== ros2_control 配置 ======================== -->
  <ros2_control name="agrobot" type="system">
    <hardware>
      <plugin>robot_base/AgrobotHardwareInterface</plugin>
      <param name="serial_port_name">/dev/STM32</param>
      <param name="serial_baud_rate">115200</param>
      <param name="wheel_radius">0.0875</param>
      <param name="wheel_separation">0.4</param>
      <param name="loop_rate">20</param>
      <param name="device_timeout">1000</param>
      <param name="imu_port">/dev/imu_usb</param>
      <param name="imu_baud_rate">115200</param>
      <param name="imu_frame_id">imu_link</param>
    </hardware>
    <joint name="left_wheel_joint">
      <command_interface name="velocity">
        <param name="min">-10.0</param>
        <param name="max">10.0</param>
      </command_interface>
      <state_interface name="position"/>
      <state_interface name="velocity"/>
    </joint>
    <joint name="right_wheel_joint">
      <command_interface name="velocity">
        <param name="min">-10.0</param>
        <param name="max">10.0</param>
      </command_interface>
      <state_interface name="position"/>
      <state_interface name="velocity"/>
    </joint>
  </ros2_control>
</robot>
