<?xml version="1.0" ?>
<!-- =================================================================================== -->
<!-- |    This document was autogenerated by xacro from src/robot_base/urdf/agrobot.xacro | -->
<!-- |    EDITING THIS FILE BY HAND IS NOT RECOMMENDED                                 | -->
<!-- =================================================================================== -->
<robot name="agrobot">
  <!-- ======================== 常用颜色 ======================== -->
  <material name="orange">
    <color rgba="1.0 0.5 0.2 1.0"/>
  </material>
  <material name="gray">
    <color rgba="0.5 0.5 0.5 1.0"/>
  </material>
  <material name="dark_gray">
    <color rgba="0.3 0.3 0.3 1.0"/>
  </material>
  <material name="blue">
    <color rgba="0.2 0.4 0.8 0.5"/>
  </material>
  <material name="black">
    <color rgba="0.1 0.1 0.1 1.0"/>
  </material>
  <material name="red">
    <color rgba="0.8 0.2 0.2 1.0"/>
  </material>
  <material name="green">
    <color rgba="0.2 0.8 0.2 1.0"/>
  </material>
  <material name="white">
    <color rgba="0.9 0.9 0.9 1.0"/>
  </material>
  <material name="silver">
    <color rgba="0.7 0.7 0.7 1.0"/>
  </material>
  <!-- z -->
  <!-- ======================== 车体结构 (核心分离部分) ======================== -->
  <link name="base_footprint"/>
  <!-- 1. base_link: 纯粹的运动学中心，无质量无外观 -->
  <joint name="base_joint" type="fixed">
    <parent link="base_footprint"/>
    <child link="base_link"/>
    <origin rpy="0 0 0" xyz="0 0 0.1875"/>
  </joint>
  <link name="base_link"/>
  <!-- 2. chassis_link: 物理车壳，挂在 base_link 后面 -->
  <joint name="chassis_joint" type="fixed">
    <parent link="base_link"/>
    <child link="chassis_link"/>
    <origin rpy="0 0 0" xyz="-0.236 0 0"/>
  </joint>
  <link name="chassis_link">
    <visual>
      <geometry>
        <box size="0.64 0.542 0.2"/>
      </geometry>
      <material name="blue"/>
    </visual>
    <collision>
      <geometry>
        <box size="0.64 0.542 0.2"/>
      </geometry>
    </collision>
    <inertial>
      <mass value="50"/>
      <inertia ixx="1.3906833333333335" ixy="0" ixz="0" iyy="1.873333333333333" iyz="0" izz="2.9306833333333335"/>
    </inertial>
  </link>
  <!-- 中间层，挂在 chassis_link 上 -->
  <joint name="base_middle_joint" type="fixed">
    <parent link="chassis_link"/>
    <child link="base_middle_link"/>
    <origin rpy="0 0 0" xyz="0 0 0.20500000000000002"/>
  </joint>
  <link name="base_middle_link">
    <visual>
      <geometry>
        <cylinder length="0.21" radius="0.3"/>
      </geometry>
      <material name="blue"/>
    </visual>
    <collision>
      <geometry>
        <cylinder length="0.21" radius="0.3"/>
      </geometry>
    </collision>
    <inertial>
      <mass value="50"/>
      <inertia ixx="1.3087499999999996" ixy="0" ixz="0" iyy="1.3087499999999996" iyz="0" izz="2.25"/>
    </inertial>
  </link>
  <!-- ======================== IMU传感器 ======================== -->
  <link name="imu_link">
    <visual>
      <geometry>
        <box size="0.02 0.02 0.01"/>
      </geometry>
      <material name="green"/>
    </visual>
    <collision>
      <geometry>
        <box size="0.02 0.02 0.01"/>
      </geometry>
    </collision>
    <inertial>
      <mass value="0.01"/>
      <inertia ixx="1e-6" ixy="0" ixz="0" iyy="1e-6" iyz="0" izz="1e-6"/>
    </inertial>
  </link>
  <!-- IMU安装在机器人车体物理中心位置，因此挂在 chassis_link -->
  <joint name="imu_joint" type="fixed">
    <parent link="chassis_link"/>
    <child link="imu_link"/>
    <origin rpy="0 0 0" xyz="-0.257 0 -0.03"/>
  </joint>
  <!-- 转向关节：绕竖直轴(Yaw)自由旋转 -->
  <link name="back_caster_fork_link"/>
  <joint name="back_caster_yaw_joint" type="continuous">
    <parent link="chassis_link"/>
    <child link="back_caster_fork_link"/>
    <origin rpy="0 0 0" xyz="-0.25 0 -0.16"/>
    <axis xyz="0 0 1"/>
    <dynamics damping="0.1" friction="0.0"/>
  </joint>
  <!-- 滚动关节：轮子绕自身轴心(Y)自由转动 -->
  <link name="back_caster_link">
    <visual>
      <origin rpy="1.570796326795 0 0" xyz="0 0 0"/>
      <geometry>
        <cylinder length="0.045" radius="0.0275"/>
      </geometry>
      <material name="gray"/>
    </visual>
    <collision>
      <origin rpy="1.570796326795 0 0" xyz="0 0 0"/>
      <geometry>
        <cylinder length="0.045" radius="0.0275"/>
      </geometry>
    </collision>
    <inertial>
      <origin rpy="1.570796326795 0 0" xyz="0 0 0"/>
      <mass value="0.1"/>
      <inertia ixx="3.578125e-05" ixy="0" ixz="0" iyy="3.578125e-05" iyz="0" izz="3.7812500000000004e-05"/>
    </inertial>
  </link>
  <joint name="back_caster_wheel_joint" type="continuous">
    <parent link="back_caster_fork_link"/>
    <child link="back_caster_link"/>
    <origin rpy="0 0 0" xyz="0 0 0"/>
    <axis xyz="0 1 0"/>
    <dynamics damping="0.05" friction="0.0"/>
  </joint>
  <link name="left_wheel_link">
    <visual>
      <origin rpy="1.570796326795 0 0" xyz="0 0 0"/>
      <geometry>
        <cylinder length="0.045" radius="0.0875"/>
      </geometry>
      <material name="black"/>
    </visual>
    <collision>
      <origin rpy="1.570796326795 0 0" xyz="0 0 0"/>
      <geometry>
        <cylinder length="0.045" radius="0.0875"/>
      </geometry>
    </collision>
    <inertial>
      <origin rpy="1.570796326795 0 0" xyz="0 0 0"/>
      <mass value="0.5"/>
      <inertia ixx="0.0010414062499999998" ixy="0" ixz="0" iyy="0.0010414062499999998" iyz="0" izz="0.0019140624999999997"/>
    </inertial>
  </link>
  <joint name="left_wheel_joint" type="continuous">
    <parent link="base_link"/>
    <child link="left_wheel_link"/>
    <origin rpy="0 0 0" xyz="0 0.306 -0.1"/>
    <axis xyz="0 1 0"/>
    <limit effort="10.0" velocity="10.0"/>
    <dynamics damping="0.1" friction="0.1"/>
  </joint>
  <link name="right_wheel_link">
    <visual>
      <origin rpy="1.570796326795 0 0" xyz="0 0 0"/>
      <geometry>
        <cylinder length="0.045" radius="0.0875"/>
      </geometry>
      <material name="black"/>
    </visual>
    <collision>
      <origin rpy="1.570796326795 0 0" xyz="0 0 0"/>
      <geometry>
        <cylinder length="0.045" radius="0.0875"/>
      </geometry>
    </collision>
    <inertial>
      <origin rpy="1.570796326795 0 0" xyz="0 0 0"/>
      <mass value="0.5"/>
      <inertia ixx="0.0010414062499999998" ixy="0" ixz="0" iyy="0.0010414062499999998" iyz="0" izz="0.0019140624999999997"/>
    </inertial>
  </link>
  <joint name="right_wheel_joint" type="continuous">
    <parent link="base_link"/>
    <child link="right_wheel_link"/>
    <origin rpy="0 0 0" xyz="0 -0.306 -0.1"/>
    <axis xyz="0 1 0"/>
    <limit effort="10.0" velocity="10.0"/>
    <dynamics damping="0.1" friction="0.1"/>
  </joint>
  <link name="right_camera">
    <visual>
      <geometry>
        <box size="0.05 0.05 0.03"/>
      </geometry>
      <material name="red"/>
    </visual>
    <collision>
      <geometry>
        <box size="0.05 0.05 0.03"/>
      </geometry>
    </collision>
    <inertial>
      <mass value="0.05"/>
      <inertia ixx="1.4166666666666668e-05" ixy="0" ixz="0" iyy="1.4166666666666668e-05" iyz="0" izz="2.083333333333334e-05"/>
    </inertial>
  </link>
  <!-- 关节名加上前缀防止重名，挂载在车体中心 -->
  <joint name="right_camera_joint" type="fixed">
    <parent link="chassis_link"/>
    <child link="right_camera"/>
    <origin rpy="0 1.570796326795 1.570796326795" xyz="0 0.251 0.335"/>
  </joint>
  <link name="front_laser_link">
    <visual>
      <origin rpy="0 0 0" xyz="0 0 0"/>
      <geometry>
        <cylinder length="0.06" radius="0.0325"/>
      </geometry>
      <material name="red"/>
    </visual>
    <collision>
      <geometry>
        <cylinder length="0.06" radius="0.0325"/>
      </geometry>
    </collision>
    <inertial>
      <mass value="0.05"/>
      <inertia ixx="5.6406250000000006e-05" ixy="0" ixz="0" iyy="5.6406250000000006e-05" iyz="0" izz="5.281250000000001e-05"/>
    </inertial>
  </link>
  <joint name="front_laser_joint" type="fixed">
    <!-- 挂载在车体中心 -->
    <parent link="chassis_link"/>
    <child link="front_laser_link"/>
    <origin rpy="0 0.7853981633975 0" xyz="0.32 -0.241 0.06"/>
  </joint>
  <!-- ======================== ros2_control 配置 ======================== -->
  <ros2_control name="agrobot" type="system">
    <hardware>
      <plugin>robot_base/AgrobotHardwareInterface</plugin>
      <param name="serial_port_name">/dev/STM32</param>
      <param name="serial_baud_rate">115200</param>
      <param name="wheel_radius">0.0875</param>
      <param name="wheel_separation">0.612</param>
      <param name="loop_rate">50</param>
      <param name="device_timeout">1000</param>
    </hardware>
    <joint name="left_wheel_joint">
      <command_interface name="velocity">
        <param name="min">-10.0</param>
        <param name="max">10.0</param>
      </command_interface>
      <state_interface name="position"/>
      <state_interface name="velocity"/>
    </joint>
    <joint name="right_wheel_joint">
      <command_interface name="velocity">
        <param name="min">-10.0</param>
        <param name="max">10.0</param>
      </command_interface>
      <state_interface name="position"/>
      <state_interface name="velocity"/>
    </joint>
  </ros2_control>
</robot>
